Workbook

Sheet Sheet1
A1: vanus: | B1: 50 | D1: vanusegrupp | E1: =INDEX(vanusegrupp!B1:B74, MATCH(B1,vanusegrupp!A1:A74, 0)) -> 7 | F1: =INDEX(vanusegrupp!C1:C74, MATCH(B1,vanusegrupp!A1:A74, 0)) -> 4
B2: toorskoor | C2: SÕNALINE | D2: SOORITUSLIK | E2: VCI | F2: POI | G2: WMI | H2: PSI
A3: piltide täiendamine | B3: 22 | D3: =MATCH(B3, OFFSET('a1'!I$2, (E$1-1) * 20, 0, 20), 1) -> 13 | F3: =D3 -> 13
A4: sõnavara | B4: 56 | C4: =MATCH(B4, OFFSET('a1'!B$2, (E$1-1) * 20, 0, 20), 1) -> 14 | E4: =C4 -> 14 | L4: toorskoor | M4: %
A5: šifreering | B5: 50 | D5: =MATCH(B5, OFFSET('a1'!J$2, (E$1-1) * 20, 0, 20), 1) -> 7 | H5: =D5 -> 7 | J5: juhuslik õppimine | K5: paaride moodustamine | L5: 8
A6: sarnasused | B6: 28 | C6: =MATCH(B6, OFFSET('a1'!C$2, (E$1-1) * 20, 0, 20), 1) -> 12 | E6: =C6 -> 12 | K6: vaba meenutamine | L6: 8
A7: kuubikud | B7: 46 | D7: =MATCH(B7, OFFSET('a1'!K$2, (E$1-1) * 20, 0, 20), 1) -> 11 | F7: =D7 -> 11 | K7: kopeerimine | L7: 109
A8: aritmeetika | B8: 12 | C8: =MATCH(B8, OFFSET('a1'!D$2, (E$1-1) * 20, 0, 20), 1) -> 8 | G8: =C8 -> 8
A9: maatriksid | B9: 24 | D9: =MATCH(B9, OFFSET('a1'!L$2, (E$1-1) * 20, 0, 20), 1) -> 15 | F9: =D9 -> 15
A10: arvumälu | B10: 12 | C10: =MATCH(B10, OFFSET('a1'!E$2, (E$1-1) * 20, 0, 20), 1) -> 7 | G10: =C10 -> 7
A11: informeeritus | B11: 20 | C11: =MATCH(B11, OFFSET('a1'!F$2, (E$1-1) * 20, 0, 20), 1) -> 11 | E11: =C11 -> 11
A12: pildiseeriad | B12: 15 | D12: =MATCH(B12, OFFSET('a1'!M$2, (E$1-1) * 20, 0, 20), 1) -> 12
A13: taibukus | B13: 25 | C13: =MATCH(B13, OFFSET('a1'!G$2, (E$1-1) * 20, 0, 20), 1) -> 11
A14: sümbolite otsimine | B14: 15 | D14: =MATCH(B14, OFFSET('a1'!N$2, (E$1-1) * 20, 0, 20), 1) -> 5 | H14: =D14 -> 5
A15: täht-number järjestus | B15: 5 | C15: =MATCH(B15, OFFSET('a1'!H$2, (E$1-1) * 20, 0, 20), 1) -> 5 | G15: =C15 -> 5
A16: kujundite moodustamine | B16: 30 | D16: =MATCH(B16, OFFSET('a1'!O$2, (E$1-1) * 20, 0, 20), 1) -> 10
C17: =C4+C6+C8+C10+C11+C13 -> 63 | D17: =D3+D5+D7+D9+D12 -> 58 | E17: =E4+E6+E11 -> 37 | F17: =F3+F7+F9 -> 39 | G17: =G8+G10+G15 -> 20 | H17: =H5+H14 -> 12
C18: =C17+D17 -> 121
B20: VIQ | C20: PIQ | D20: FSIQ | E20: VCI | F20: POI | G20: WMI | H20: PSI
A21: standardiseeritud skooride summa | B21: =C17 -> 63 | C21: =D17 -> 58 | D21: =C18 -> 121 | E21: =E17 -> 37 | F21: =F17 -> 39 | G21: =G17 -> 20 | H21: =H17 -> 12
A22: IQ indeksskoorid | B22: =INDEX('a2'!B3:B111, MATCH(B21, 'a2'!A3:A111, 0)) -> 103 | C22: =INDEX('a3'!B3:B93, MATCH(C21, 'a3'!A3:A93, 0)) -> 110 | D22: =INDEX('a4'!B3:B201, MATCH(D21, 'a4'!A3:A201, 0)) -> 107 | E22: =INDEX('a5'!B3:B57, MATCH(E21, 'a5'!A3:A57, 0)) -> 114 | F22: =INDEX('a6'!B3:B57, MATCH(F21, 'a6'!A3:A57, 0)) -> 118 | G22: =INDEX('a7'!B3:B57, MATCH(G21, 'a7'!A3:A57, 0)) -> 78 | H22: =INDEX('a8'!B3:B39, MATCH(H21, 'a8'!A3:A39, 0)) -> 77
A23: protsentiilid | B23: =INDEX('a2'!C3:C111, MATCH(B21, 'a2'!A3:A111, 0)) -> 58 | C23: =INDEX('a3'!C3:C93, MATCH(C21, 'a3'!A3:A93, 0)) -> 75 | D23: =INDEX('a4'!C3:C201, MATCH(D21, 'a4'!A3:A201, 0)) -> 68 | E23: =INDEX('a5'!C3:C57, MATCH(E21, 'a5'!A3:A57, 0)) -> 82 | F23: =INDEX('a6'!C3:C57, MATCH(F21, 'a6'!A3:A57, 0)) -> 88 | G23: =INDEX('a7'!C3:C57, MATCH(G21, 'a7'!A3:A57, 0)) -> 7 | H23: =INDEX('a8'!C3:C39, MATCH(H21, 'a8'!A3:A39, 0)) -> 6
A24: usaldusvahemik 95% | B24: =INDEX('a2'!F3:F111, MATCH(B21, 'a2'!A3:A111, 0)) -> 97 | C24: =INDEX('a3'!F3:F93, MATCH(C21, 'a3'!A3:A93, 0)) -> 102 | D24: =INDEX('a4'!F3:F201, MATCH(D21, 'a4'!A3:A201, 0)) -> 102 | E24: =INDEX('a5'!F3:F57, MATCH(E21, 'a5'!A3:A57, 0)) -> 106 | F24: =INDEX('a6'!F3:F57, MATCH(F21, 'a6'!A3:A57, 0)) -> 108 | G24: =INDEX('a7'!F3:F57, MATCH(G21, 'a7'!A3:A57, 0)) -> 72 | H24: =INDEX('a8'!F3:F39, MATCH(H21, 'a8'!A3:A39, 0)) -> 71
B25: =INDEX('a2'!G3:G111, MATCH(B21, 'a2'!A3:A111, 0)) -> 108 | C25: =INDEX('a3'!G3:G93, MATCH(C21, 'a3'!A3:A93, 0)) -> 117 | D25: =INDEX('a4'!G3:G201, MATCH(D21, 'a4'!A3:A201, 0)) -> 112 | E25: =INDEX('a5'!G3:G57, MATCH(E21, 'a5'!A3:A57, 0)) -> 120 | F25: =INDEX('a6'!G3:G57, MATCH(F21, 'a6'!A3:A57, 0)) -> 125 | G25: =INDEX('a7'!G3:G57, MATCH(G21, 'a7'!A3:A57, 0)) -> 89 | H25: =INDEX('a8'!G3:G39, MATCH(H21, 'a8'!A3:A39, 0)) -> 87
B27: sõnaline | C27: soorituslik | D27: üld
A28: summa | B28: =SUM(C3:C16) -> 68 | C28: =SUM(D3:D16) -> 73 | D28: =B28+C28 -> 141
A29: keskmine | B29: =B28/7 -> 9.7142857 | C29: =C28/7 -> 10.428571 | D29: =D28/14 -> 10.071429
B31: st skoor | C31: keskmine | D31: erinevus | E31: piir | F31: tugev külg | G31: nõrk külg
A32: sõnavara | B32: =C4 -> 14 | C32: =IF(I$33="erinevus üldkeskmisest",D$29,B$29) -> 10.071429 | D32: =B32-C32 -> 3.9285714 | E32: =IF(I$33="erinevus üldkeskmisest",'b3'!C2,'b3'!B2) -> 4.09 | F32: =IF(D32>E32,"T","") | G32: =IF(D32*-1>E32, "N", "") | I32: VIQPIQ vahe: | J32: =ABS(B22-C22) -> 7
A33: sarnasused | B33: =C6 -> 12 | C33: =IF(I$33="erinevus üldkeskmisest",D$29,B$29) -> 10.071429 | D33: =B33-C33 -> 1.9285714 | E33: =IF(I$33="erinevus üldkeskmisest",'b3'!C3,'b3'!B3) -> 4.35 | F33: =IF(D33>E33,"T","") | G33: =IF(D33*-1>E33, "N", "") | I33: =IF(J32>=17, "erinevus sõnalisest keskmisest ja soorituslikust keskmisest", "erinevus üldkeskmisest") -> erinevus üldkeskmisest
A34: aritmeetika | B34: =C8 -> 8 | C34: =IF(I$33="erinevus üldkeskmisest",D$29,B$29) -> 10.071429 | D34: =B34-C34 -> -2.0714286 | E34: =IF(I$33="erinevus üldkeskmisest",'b3'!C4,'b3'!B4) -> 4.32 | F34: =IF(D34>E34,"T","") | G34: =IF(D34*-1>E34, "N", "")
A35: arvumälu | B35: =C10 -> 7 | C35: =IF(I$33="erinevus üldkeskmisest",D$29,B$29) -> 10.071429 | D35: =B35-C35 -> -3.0714286 | E35: =IF(I$33="erinevus üldkeskmisest",'b3'!C5,'b3'!B5) -> 4.35 | F35: =IF(D35>E35,"T","") | G35: =IF(D35*-1>E35, "N", "")
A36: informeeritus | B36: =C11 -> 11 | C36: =IF(I$33="erinevus üldkeskmisest",D$29,B$29) -> 10.071429 | D36: =B36-C36 -> 0.92857143 | E36: =IF(I$33="erinevus üldkeskmisest",'b3'!C6,'b3'!B6) -> 4.09 | F36: =IF(D36>E36,"T","") | G36: =IF(D36*-1>E36, "N", "")
A37: taibukus | B37: =C13 -> 11 | C37: =IF(I$33="erinevus üldkeskmisest",D$29,B$29) -> 10.071429 | D37: =B37-C37 -> 0.92857143 | E37: =IF(I$33="erinevus üldkeskmisest",'b3'!C7,'b3'!B7) -> 4.3 | F37: =IF(D37>E37,"T","") | G37: =IF(D37*-1>E37, "N", "")
A38: täht-number järjestus | B38: =C15 -> 5 | C38: =IF(I$33="erinevus üldkeskmisest",D$29,B$29) -> 10.071429 | D38: =B38-C38 -> -5.0714286 | E38: =IF(I$33="erinevus üldkeskmisest",'b3'!C8,'b3'!B8) -> 4.49 | F38: =IF(D38>E38,"T","") | G38: =IF(D38*-1>E38, "N", "") -> N
A39: piltide täiendamine | B39: =D3 -> 13 | C39: =IF(I$33="erinevus üldkeskmisest",D$29,C$29) -> 10.071429 | D39: =B39-C39 -> 2.9285714 | E39: =IF(I$33="erinevus üldkeskmisest",'b3'!C9,'b3'!B9) -> 4.56 | F39: =IF(D39>E39,"T","") | G39: =IF(D39*-1>E39, "N", "")
A40: šifreering | B40: =D5 -> 7 | C40: =IF(I$33="erinevus üldkeskmisest",D$29,C$29) -> 10.071429 | D40: =B40-C40 -> -3.0714286 | E40: =IF(I$33="erinevus üldkeskmisest",'b3'!C10,'b3'!B10) -> 4.05 | F40: =IF(D40>E40,"T","") | G40: =IF(D40*-1>E40, "N", "")
A41: kuubikud | B41: =D7 -> 11 | C41: =IF(I$33="erinevus üldkeskmisest",D$29,C$29) -> 10.071429 | D41: =B41-C41 -> 0.92857143 | E41: =IF(I$33="erinevus üldkeskmisest",'b3'!C11,'b3'!B11) -> 4.42 | F41: =IF(D41>E41,"T","") | G41: =IF(D41*-1>E41, "N", "")
A42: maatriksid | B42: =D9 -> 15 | C42: =IF(I$33="erinevus üldkeskmisest",D$29,C$29) -> 10.071429 | D42: =B42-C42 -> 4.9285714 | E42: =IF(I$33="erinevus üldkeskmisest",'b3'!C12,'b3'!B12) -> 4.12 | F42: =IF(D42>E42,"T","") -> T | G42: =IF(D42*-1>E42, "N", "")
A43: pildiseeriad | B43: =D12 -> 12 | C43: =IF(I$33="erinevus üldkeskmisest",D$29,C$29) -> 10.071429 | D43: =B43-C43 -> 1.9285714 | E43: =IF(I$33="erinevus üldkeskmisest",'b3'!C13,'b3'!B13) -> 4.94 | F43: =IF(D43>E43,"T","") | G43: =IF(D43*-1>E43, "N", "")
...

Sheet a1
A1: st skoor | B1: Sõnavara | C1: Sarnasused | D1: Aritmeetika | E1: Arvumälu | F1: Informeeritus | G1: Taibukus | H1: T-N järjest | I1: P täiend | J1: Šifreering | K1: Kuubikud | L1: Maatriksid | M1: Pildiseeriad | N1: S otsimine | O1: K moodust
A2: 1 | B2: 0 | C2: 0 | D2: 0 | E2: 0 | F2: 0 | G2: 0 | H2: 0 | I2: 0 | J2: 0 | K2: 0 | L2: 0 | M2: 0 | N2: 0 | O2: 0
A3: 2 | B3: 5 | C3: 3 | D3: 2 | E3: 3 | F3: 1 | G3: 3 | H3: 2 | I3: 5 | J3: 20 | K3: 8 | L3: 3 | M3: 2 | N3: 4 | O3: 6
A4: 3 | B4: 11 | C4: 6 | D4: 5 | E4: 5 | F4: 2 | G4: 6 | H4: 3 | I4: 8 | J4: 35 | K4: 16 | L4: 6 | M4: 4 | N4: 9 | O4: 11
A5: 4 | B5: 17 | C5: 9 | D5: 7 | E5: 7 | F5: 3 | G5: 9 | H5: 5 | I5: 11 | J5: 43 | K5: 21 | L5: 9 | M5: 6 | N5: 15 | O5: 15
A6: 5 | B6: 22 | C6: 13 | D6: 8 | E6: 10 | F6: 5 | G6: 12 | H6: 6 | I6: 14 | J6: 49 | K6: 26 | L6: 11 | M6: 8 | N6: 20 | O6: 19
A7: 6 | B7: 27 | C7: 16 | D7: 9 | E7: 12 | F7: 7 | G7: 14 | H7: 7 | I7: 16 | J7: 55 | K7: 31 | L7: 13 | M7: 10 | N7: 24 | O7: 22
A8: 7 | B8: 31 | C8: 18 | D8: 11 | E8: 13 | F8: 9 | G8: 16 | H8: 8 | I8: 18 | J8: 61 | K8: 35 | L8: 15 | M8: 11 | N8: 28 | O8: 25
A9: 8 | B9: 35 | C9: 20 | D9: 12 | E9: 15 | F9: 11 | G9: 18 | H9: 9 | I9: 19 | J9: 67 | K9: 39 | L9: 17 | M9: 13 | N9: 31 | O9: 29
A10: 9 | B10: 38 | C10: 22 | D10: 13 | E10: 16 | F10: 14 | G10: 20 | H10: 10 | I10: 20 | J10: 72 | K10: 43 | L10: 19 | M10: 14 | N10: 34 | O10: 32
A11: 10 | B11: 41 | C11: 24 | D11: 15 | E11: 17 | F11: 16 | G11: 22 | H11: 11 | I11: 21 | J11: 77 | K11: 48 | L11: 20 | M11: 15 | N11: 36 | O11: 35
A12: 11 | B12: 43 | C12: 25 | D12: 16 | E12: 18 | F12: 18 | G12: 24 | H12: 12 | J12: 83 | K12: 52 | L12: 21 | M12: 17 | N12: 39 | O12: 38
A13: 12 | B13: 46 | C13: 27 | D13: 17 | E13: 20 | F13: 20 | G13: 25 | H13: 13 | I13: 22 | J13: 88 | K13: 56 | L13: 23 | M13: 18 | N13: 42 | O13: 40
A14: 13 | B14: 48 | C14: 29 | D14: 18 | E14: 21 | F14: 22 | G14: 26 | H14: 14 | J14: 93 | K14: 59 | L14: 24 | M14: 19 | N14: 45 | O14: 43
A15: 14 | B15: 51 | C15: 30 | D15: 19 | E15: 23 | F15: 23 | G15: 28 | H15: 15 | I15: 23 | J15: 97 | K15: 62 | L15: 25 | M15: 20 | N15: 48 | O15: 45
A16: 15 | B16: 54 | C16: 31 | D16: 20 | E16: 24 | F16: 24 | G16: 29 | H16: 16 | I16: 24 | J16: 102 | K16: 64 | N16: 51 | O16: 48
A17: 16 | B17: 57 | C17: 32 | D17: 21 | E17: 25 | F17: 26 | G17: 30 | H17: 17 | J17: 106 | K17: 66 | L17: 26 | M17: 21 | N17: 54 | O17: 50
A18: 17 | B18: 59 | C18: 33 | D18: 22 | E18: 27 | F18: 27 | G18: 31 | H18: 18 | I18: 25 | J18: 113 | K18: 68 | M18: 22 | N18: 56 | O18: 52
A19: 18 | B19: 62 | C19: 34 | E19: 28 | F19: 28 | G19: 32 | H19: 20 | J19: 119 | N19: 59
A20: 19 | B20: 64 | C20: 35 | E20: 30 | G20: 33 | H20: 21 | J20: 125
A22: 1 | B22: 0 | C22: 0 | D22: 0 | E22: 0 | F22: 0 | G22: 0 | H22: 0 | I22: 0 | J22: 0 | K22: 0 | L22: 0 | M22: 0 | N22: 0 | O22: 0
A23: 2 | B23: 6 | C23: 3 | D23: 2 | E23: 3 | F23: 1 | G23: 3 | H23: 2 | I23: 5 | J23: 19 | K23: 8 | L23: 3 | M23: 2 | N23: 4 | O23: 6
A24: 3 | B24: 12 | C24: 6 | D24: 5 | E24: 5 | F24: 2 | G24: 6 | H24: 3 | I24: 8 | J24: 34 | K24: 16 | L24: 6 | M24: 4 | N24: 9 | O24: 11
A25: 4 | B25: 17 | C25: 9 | D25: 7 | E25: 7 | F25: 3 | G25: 9 | H25: 5 | I25: 11 | J25: 42 | K25: 21 | L25: 9 | M25: 6 | N25: 15 | O25: 15
A26: 5 | B26: 22 | C26: 13 | D26: 8 | E26: 10 | F26: 5 | G26: 12 | H26: 6 | I26: 14 | J26: 49 | K26: 26 | L26: 11 | M26: 8 | N26: 20 | O26: 18
A27: 6 | B27: 27 | C27: 16 | D27: 9 | E27: 12 | F27: 7 | G27: 14 | H27: 7 | I27: 16 | J27: 55 | K27: 31 | L27: 13 | M27: 10 | N27: 24 | O27: 22
A28: 7 | B28: 31 | C28: 19 | D28: 11 | E28: 13 | F28: 9 | G28: 16 | H28: 8 | I28: 18 | J28: 60 | K28: 35 | L28: 15 | M28: 11 | N28: 28 | O28: 25
A29: 8 | B29: 35 | C29: 21 | D29: 12 | E29: 15 | F29: 11 | G29: 18 | H29: 9 | I29: 19 | J29: 66 | K29: 39 | L29: 17 | M29: 13 | N29: 31 | O29: 29
A30: 9 | B30: 38 | C30: 22 | D30: 13 | E30: 16 | F30: 14 | G30: 20 | H30: 10 | I30: 20 | J30: 71 | K30: 43 | L30: 19 | M30: 14 | N30: 34 | O30: 33
A31: 10 | B31: 41 | C31: 24 | D31: 15 | E31: 17 | F31: 16 | G31: 22 | H31: 11 | I31: 21 | J31: 77 | K31: 48 | L31: 20 | M31: 15 | N31: 36 | O31: 36
A32: 11 | B32: 44 | C32: 25 | D32: 16 | E32: 18 | F32: 18 | G32: 24 | H32: 12 | J32: 82 | K32: 52 | L32: 21 | M32: 17 | N32: 39 | O32: 39
A33: 12 | B33: 47 | C33: 27 | D33: 17 | E33: 20 | F33: 20 | G33: 26 | H33: 13 | I33: 22 | J33: 87 | K33: 56 | L33: 23 | M33: 18 | N33: 42 | O33: 41
A34: 13 | B34: 50 | C34: 29 | D34: 18 | E34: 21 | F34: 22 | G34: 27 | H34: 14 | J34: 92 | K34: 59 | L34: 24 | M34: 19 | N34: 45 | O34: 44
A35: 14 | B35: 52 | C35: 30 | D35: 19 | E35: 23 | F35: 24 | G35: 28 | H35: 15 | I35: 23 | J35: 97 | K35: 62 | L35: 25 | M35: 20 | N35: 48 | O35: 46
A36: 15 | B36: 54 | C36: 31 | D36: 20 | E36: 24 | F36: 25 | G36: 29 | H36: 16 | I36: 24 | J36: 102 | K36: 64 | N36: 51 | O36: 48
A37: 16 | B37: 57 | C37: 32 | D37: 21 | E37: 25 | F37: 27 | G37: 31 | H37: 17 | J37: 107 | K37: 66 | L37: 26 | M37: 21 | N37: 54 | O37: 50
A38: 17 | B38: 59 | C38: 33 | D38: 22 | E38: 27 | F38: 28 | G38: 32 | H38: 18 | I38: 25 | J38: 113 | K38: 68 | M38: 22 | N38: 56 | O38: 52
A39: 18 | B39: 62 | C39: 34 | E39: 28 | G39: 33 | H39: 20 | J39: 118 | N39: 59
A40: 19 | B40: 64 | C40: 35 | E40: 30 | H40: 21 | J40: 125
A42: 1 | B42: 0 | C42: 0 | D42: 0 | E42: 0 | F42: 0 | G42: 0 | H42: 0 | I42: 0 | J42: 0 | K42: 0 | L42: 0 | M42: 0 | N42: 0 | O42: 0
...

Sheet a2
A1: sõnaline | D1: 0.9 | F1: 0.95
A2: st skooride summa | B2: VIQ | C2: protsentiil | D2: min | E2: max | F2: min | G2: max
A3: 6 | B3: 40 | C3: <0,1 | F3: 37 | G3: 49
A4: 7 | B4: 43 | C4: <0,1 | F4: 40 | G4: 52
A5: 8 | B5: 46 | C5: <0,1 | F5: 42 | G5: 54
A6: 9 | B6: 49 | C6: <0,1 | F6: 45 | G6: 57
A7: 10 | B7: 52 | C7: 0.1 | F7: 48 | G7: 60
A8: 11 | B8: 55 | C8: 0.1 | F8: 51 | G8: 63
A9: 12 | B9: 56 | C9: 0.2 | F9: 52 | G9: 64
A10: 13 | B10: 57 | C10: 0.2 | F10: 53 | G10: 65
A11: 14 | B11: 58 | C11: 0.3 | F11: 54 | G11: 66
A12: 15 | B12: 59 | C12: 0.3 | F12: 55 | G12: 67
A13: 16 | B13: 60 | C13: 0.4 | F13: 56 | G13: 68
A14: 17 | B14: 61 | C14: 0.5 | F14: 57 | G14: 69
A15: 18 | B15: 62 | C15: 1 | F15: 58 | G15: 70
A16: 19 | B16: 63 | C16: 1 | F16: 59 | G16: 71
A17: 20 | B17: 64 | C17: 1 | F17: 60 | G17: 72
A18: 21 | B18: 65 | C18: 1 | F18: 61 | G18: 73
... A101: 104 | B101: 148 | C101: 99.9 | F101: 140 | G101: 152
A102: 105 | B102: 150 | C102: >99,9 | F102: 142 | G102: 154
A103: 106 | B103: 152 | C103: >99,9 | F103: 144 | G103: 156
A104: 107 | B104: 154 | C104: >99,9 | F104: 146 | G104: 158
A105: 108 | B105: 156 | C105: >99,9 | F105: 147 | G105: 159
A106: 109 | B106: 158 | C106: >99,9 | F106: 149 | G106: 161
A107: 110 | B107: 160 | C107: >99,9 | F107: 151 | G107: 163
A108: 111 | B108: 160 | C108: >99,9 | F108: 151 | G108: 163
A109: 112 | B109: 160 | C109: >99,9 | F109: 151 | G109: 163
A110: 113 | B110: 160 | C110: >99,9 | F110: 151 | G110: 163
A111: 114 | B111: 160 | C111: >99,9 | F111: 151 | G111: 163

Sheet a3
A1: soorituslik | D1: 0.9 | F1: 0.95
A2: st skooride summa | B2: PIQ | C2: protsentiil | D2: min | E2: max | F2: min | G2: max
A3: 5 | B3: 40 | C3: <0,1 | F3: 37 | G3: 53
A4: 6 | B4: 43 | C4: <0,1 | F4: 40 | G4: 55
A5: 7 | B5: 46 | C5: <0,1 | F5: 43 | G5: 58
A6: 8 | B6: 50 | C6: <0,1 | F6: 46 | G6: 62
A7: 9 | B7: 53 | C7: 0.1 | F7: 49 | G7: 64
A8: 10 | B8: 55 | C8: 0.1 | F8: 51 | G8: 66
A9: 11 | B9: 57 | C9: 0.2 | F9: 53 | G9: 68
A10: 12 | B10: 58 | C10: 0.3 | F10: 54 | G10: 69
A11: 13 | B11: 60 | C11: 0.4 | F11: 56 | G11: 71
A12: 14 | B12: 61 | C12: 0.5 | F12: 56 | G12: 72
A13: 15 | B13: 62 | C13: 1 | F13: 57 | G13: 72
A14: 16 | B14: 63 | C14: 1 | F14: 58 | G14: 74
A15: 17 | B15: 63 | C15: 1 | F15: 58 | G15: 74
A16: 18 | B16: 64 | C16: 1 | F16: 59 | G16: 75
A17: 19 | B17: 64 | C17: 1 | F17: 59 | G17: 74
A18: 20 | B18: 65 | C18: 1 | F18: 60 | G18: 76
... A75: 77 | B75: 148 | C75: 99.9 | F75: 137 | G75: 152
A76: 78 | B76: 150 | C76: >99,9 | F76: 138 | G76: 154
A77: 79 | B77: 152 | C77: >99,9 | F77: 140 | G77: 155
A78: 80 | B78: 154 | C78: >99,9 | F78: 142 | G78: 157
A79: 81 | B79: 156 | C79: >99,9 | F79: 144 | G79: 159
A80: 82 | B80: 158 | C80: >99,9 | F80: 146 | G80: 161
A81: 83 | B81: 160 | C81: >99,9 | F81: 147 | G81: 163
A82: 84 | B82: 160 | C82: >99,9 | F82: 147 | G82: 163
A83: 85 | B83: 160 | C83: >99,9 | F83: 147 | G83: 163
A84: 86 | B84: 160 | C84: >99,9 | F84: 147 | G84: 163
A85: 87 | B85: 160 | C85: >99,9 | F85: 147 | G85: 163
A86: 88 | B86: 160 | C86: >99,9 | F86: 147 | G86: 163
A87: 89 | B87: 160 | C87: >99,9 | F87: 147 | G87: 163
... A93: 95 | B93: 160 | C93: >99,9 | F93: 147 | G93: 163

Sheet a4
A1: koguskaala | D1: 0.9 | F1: 0.95
A2: st skooride summa | B2: FSIQ | C2: protsentiil | D2: min | E2: max | F2: min | G2: max
A3: 11 | B3: 40 | C3: <0,1 | F3: 37 | G3: 47
A4: 12 | B4: 42 | C4: <0,1 | F4: 39 | G4: 49
A5: 13 | B5: 44 | C5: <0,1 | F5: 41 | G5: 51
A6: 14 | B6: 46 | C6: <0,1 | F6: 43 | G6: 53
A7: 15 | B7: 48 | C7: <0,1 | F7: 45 | G7: 55
A8: 16 | B8: 50 | C8: <0,1 | F8: 46 | G8: 57
A9: 17 | B9: 51 | C9: 0.1 | F9: 47 | G9: 58
A10: 18 | B10: 52 | C10: 0.1 | F10: 48 | G10: 59
A11: 19 | B11: 53 | C11: 0.1 | F11: 49 | G11: 60
A12: 20 | B12: 54 | C12: 0.1 | F12: 50 | G12: 61
A13: 21 | B13: 55 | C13: 0.1 | F13: 51 | G13: 62
A14: 22 | B14: 56 | C14: 0.1 | F14: 52 | G14: 63
A15: 23 | B15: 56 | C15: 0.2 | F15: 52 | G15: 63
A16: 24 | B16: 57 | C16: 0.2 | F16: 53 | G16: 64
A17: 25 | B17: 57 | C17: 0.2 | F17: 53 | G17: 64
A18: 26 | B18: 58 | C18: 0.3 | F18: 54 | G18: 65
A19: 27 | B19: 59 | C19: 0.3 | F19: 55 | G19: 66
A20: 28 | B20: 59 | C20: 0.3 | F20: 55 | G20: 66
... A165: 173 | B165: 149 | C165: 99.9 | F165: 142 | G165: 153
A166: 174 | B166: 150 | C166: >99,9 | F166: 143 | G166: 154
A167: 175 | B167: 151 | C167: >99,9 | F167: 144 | G167: 155
A168: 176 | B168: 152 | C168: >99,9 | F168: 145 | G168: 155
A169: 177 | B169: 153 | C169: >99,9 | F169: 146 | G169: 156
A170: 178 | B170: 154 | C170: >99,9 | F170: 147 | G170: 157
A171: 179 | B171: 155 | C171: >99,9 | F171: 148 | G171: 158
A172: 180 | B172: 156 | C172: >99,9 | F172: 149 | G172: 159
A173: 181 | B173: 157 | C173: >99,9 | F173: 150 | G173: 160
A174: 182 | B174: 158 | C174: >99,9 | F174: 151 | G174: 161
A175: 183 | B175: 159 | C175: >99,9 | F175: 152 | G175: 162
A176: 184 | B176: 160 | C176: >99,9 | F176: 153 | G176: 163
A177: 185 | B177: 160 | C177: >99,9 | F177: 153 | G177: 163
... A201: 209 | B201: 160 | C201: >99,9 | F201: 153 | G201: 163

Sheet a5
A1: sõnaline taibukus | D1: 0.9 | F1: 0.95
A2: st skooride summa | B2: VCI | C2: protsentiil | D2: min | E2: max | F2: min | G2: max
A3: 3 | B3: 45 | C3: <0,1 | F3: 42 | G3: 55
A4: 4 | B4: 50 | C4: <0,1 | F4: 46 | G4: 60
A5: 5 | B5: 55 | C5: 0.1 | F5: 51 | G5: 65
A6: 6 | B6: 60 | C6: 0.4 | F6: 56 | G6: 70
A7: 7 | B7: 62 | C7: 1 | F7: 58 | G7: 72
A8: 8 | B8: 63 | C8: 1 | F8: 59 | G8: 73
A9: 9 | B9: 64 | C9: 1 | F9: 59 | G9: 73
A10: 10 | B10: 65 | C10: 1 | F10: 60 | G10: 74
A11: 11 | B11: 67 | C11: 1 | F11: 62 | G11: 76
A12: 12 | B12: 68 | C12: 2 | F12: 63 | G12: 77
A13: 13 | B13: 69 | C13: 2 | F13: 64 | G13: 78
A14: 14 | B14: 70 | C14: 2 | F14: 65 | G14: 79
A15: 15 | B15: 72 | C15: 3 | F15: 67 | G15: 81
A16: 16 | B16: 74 | C16: 4 | F16: 69 | G16: 83
... A53: 53 | B53: 148 | C53: 99.9 | F53: 138 | G53: 152
A54: 54 | B54: 150 | C54: >99,9 | F54: 140 | G54: 154
A55: 55 | B55: 152 | C55: >99,9 | F55: 142 | G55: 156
A56: 56 | B56: 155 | C56: >99,9 | F56: 145 | G56: 158
A57: 57 | B57: 155 | C57: >99,9 | F57: 145 | G57: 158

Sheet a6
A1: tajupõhine töötlus | D1: 0.9 | F1: 0.95
A2: st skooride summa | B2: POI | C2: protsentiil | D2: min | E2: max | F2: min | G2: max
A3: 3 | B3: 45 | C3: <0,1 | F3: 42 | G3: 59
A4: 4 | B4: 50 | C4: <0,1 | F4: 47 | G4: 63
A5: 5 | B5: 55 | C5: 0.1 | F5: 51 | G5: 68
A6: 6 | B6: 56 | C6: 0.2 | F6: 52 | G6: 69
A7: 7 | B7: 58 | C7: 0.3 | F7: 54 | G7: 71
A8: 8 | B8: 60 | C8: 0.4 | F8: 56 | G8: 72
A9: 9 | B9: 63 | C9: 1 | F9: 58 | G9: 75
A10: 10 | B10: 65 | C10: 1 | F10: 60 | G10: 77
A11: 11 | B11: 65 | C11: 1 | F11: 60 | G11: 77
A12: 12 | B12: 66 | C12: 1 | F12: 61 | G12: 78
A13: 13 | B13: 67 | C13: 1 | F13: 62 | G13: 79
A14: 14 | B14: 69 | C14: 2 | F14: 64 | G14: 80
A15: 15 | B15: 70 | C15: 2 | F15: 65 | G15: 82
A16: 16 | B16: 73 | C16: 4 | F16: 67 | G16: 84
... A47: 47 | B47: 148 | C47: 99.9 | F47: 135 | G47: 152
A48: 48 | B48: 152 | C48: >99,9 | F48: 138 | G48: 155
A49: 49 | B49: 155 | C49: >99,9 | F49: 141 | G49: 158
A50: 50 | B50: 155 | C50: >99,9 | F50: 141 | G50: 158
A51: 51 | B51: 155 | C51: >99,9 | F51: 141 | G51: 158
A52: 52 | B52: 155 | C52: >99,9 | F52: 141 | G52: 158
A53: 53 | B53: 155 | C53: >99,9 | F53: 141 | G53: 158
A54: 54 | B54: 155 | C54: >99,9 | F54: 141 | G54: 158
A55: 55 | B55: 155 | C55: >99,9 | F55: 141 | G55: 158
A56: 56 | B56: 155 | C56: >99,9 | F56: 141 | G56: 158
A57: 57 | B57: 155 | C57: >99,9 | F57: 141 | G57: 158

Sheet a7
A1: töömälu | D1: 0.9 | F1: 0.95
A2: st skooride summa | B2: WMI | C2: protsentiil | D2: min | E2: max | F2: min | G2: max
A3: 3 | B3: 45 | C3: <0,1 | F3: 42 | G3: 59
A4: 4 | B4: 49 | C4: <0,1 | F4: 46 | G4: 63
A5: 5 | B5: 52 | C5: 0.1 | F5: 48 | G5: 65
A6: 6 | B6: 55 | C6: 0.1 | F6: 51 | G6: 68
A7: 7 | B7: 57 | C7: 0.2 | F7: 53 | G7: 70
A8: 8 | B8: 59 | C8: 0.3 | F8: 55 | G8: 72
A9: 9 | B9: 62 | C9: 1 | F9: 57 | G9: 74
A10: 10 | B10: 63 | C10: 1 | F10: 59 | G10: 75
A11: 11 | B11: 64 | C11: 1 | F11: 59 | G11: 76
A12: 12 | B12: 65 | C12: 1 | F12: 60 | G12: 77
A13: 13 | B13: 67 | C13: 1 | F13: 62 | G13: 78
A14: 14 | B14: 70 | C14: 2 | F14: 65 | G14: 82
A15: 15 | B15: 71 | C15: 3 | F15: 65 | G15: 82
A16: 16 | B16: 72 | C16: 3 | F16: 67 | G16: 83
... A51: 51 | B51: 148 | C51: 99.9 | F51: 135 | G51: 152
A52: 52 | B52: 150 | C52: >99,9 | F52: 136 | G52: 153
A53: 53 | B53: 152 | C53: >99,9 | F53: 138 | G53: 155
A54: 54 | B54: 155 | C54: >99,9 | F54: 141 | G54: 158
A55: 55 | B55: 155 | C55: >99,9 | F55: 141 | G55: 158
A56: 56 | B56: 155 | C56: >99,9 | F56: 141 | G56: 158
A57: 57 | B57: 155 | C57: >99,9 | F57: 141 | G57: 158

Sheet a8
A1: töötluskiirus | D1: 0.9 | F1: 0.95
A2: st skooride summa | B2: PSI | C2: protsentiil | D2: min | E2: max | F2: min | G2: max
A3: 2 | B3: 45 | C3: <0,1 | F3: 42 | G3: 57
A4: 3 | B4: 51 | C4: 0.1 | F4: 47 | G4: 63
A5: 4 | B5: 59 | C5: 0.3 | F5: 55 | G5: 70
A6: 5 | B6: 61 | C6: 0.5 | F6: 56 | G6: 72
A7: 6 | B7: 62 | C7: 1 | F7: 58 | G7: 73
A8: 7 | B8: 65 | C8: 1 | F8: 60 | G8: 75
A9: 8 | B9: 66 | C9: 1 | F9: 61 | G9: 76
A10: 9 | B10: 67 | C10: 1 | F10: 62 | G10: 78
A11: 10 | B11: 71 | C11: 3 | F11: 66 | G11: 81
A12: 11 | B12: 74 | C12: 4 | F12: 69 | G12: 84
A13: 12 | B13: 77 | C13: 6 | F13: 71 | G13: 87
A14: 13 | B14: 79 | C14: 9 | F14: 73 | G14: 89
A15: 14 | B15: 81 | C15: 10 | F15: 75 | G15: 91
... A36: 35 | B36: 148 | C36: 99.9 | F36: 137 | G36: 152
A37: 36 | B37: 150 | C37: >99,9 | F37: 138 | G37: 154
A38: 37 | B38: 153 | C38: >99,9 | F38: 141 | G38: 156
A39: 38 | B39: 155 | C39: >99,9 | F39: 143 | G39: 158

Sheet a10
B1: juhuslik õppimine - paaride moodustamine | C1: juhuslik õppimine - vaba meenutamine | D1: kopeerimine
A2: <1 | B2: 0 | C2: 0
A3: 1 | B3: 1 | C3: 1 | D3: 40 | F3: 1 | G3: 3 | H3: 3 | I3: 64 | K3: 1 | L3: 1 | M3: 3 | N3: 42 | P3: 1 | Q3: 0 | R3: 1 | S3: 23 | U3: 1 | V3: 0 | W3: 1 | X3: 26
A4: 1-2 | B4: 2 | C4: 2
A5: 2 | B5: 5 | C5: 4 | D5: 48 | F5: 2 | G5: 5 | H5: 4 | I5: 69 | K5: 2 | L5: 2 | M5: 4 | N5: 60 | P5: 2 | Q5: 1 | R5: 3 | S5: 57 | U5: 2 | V5: 1 | W5: 2 | X5: 33
A6: 2-5 | B6: 6 | C6: 5
A7: 5 | B7: 7 | C7: 6 | D7: 65 | F7: 5 | G7: 7 | H7: 5 | I7: 77 | K7: 5 | L7: 6 | M7: 5 | N7: 68 | P7: 5 | Q7: 4 | R7: 5 | S7: 65 | U7: 5 | V7: 2 | W7: 5 | X7: 38
A8: 5-10 | B8: 8
A9: 10 | B9: 10 | C9: 7 | D9: 89 | F9: 10 | G9: 8 | H9: 6 | I9: 84 | K9: 10 | L9: 8 | M9: 6 | N9: 83 | P9: 10 | Q9: 6 | R9: 6 | S9: 74 | U9: 10 | V9: 4 | W9: 5 | X9: 44
A10: 10-25 | B10: 11
A11: 25 | B11: 14 | C11: 7 | D11: 106 | F11: 25 | G11: 12 | H11: 8 | I11: 101 | K11: 25 | L11: 10 | M11: 7 | N11: 100 | P11: 25 | Q11: 8 | R11: 7 | S11: 91 | U11: 25 | V11: 6 | W11: 6 | X11: 59
A12: 25-50 | B12: 15
A13: 50 | B13: 16 | C13: 8 | D13: 119 | F13: 50 | G13: 16 | H13: 8 | I13: 124 | K13: 50 | L13: 14 | M13: 8 | N13: 120 | P13: 50 | Q13: 12 | R13: 8 | S13: 103 | U13: 50 | V13: 10 | W13: 7 | X13: 74
A14: >50 | B14: 17

Sheet b1
A2: VIQ-PIQ | B2: 12.84
A3: VCI-POI | B3: 14.46
A4: VCI-WMI | B4: 13.48
A5: POI-PSI | B5: 13.99
A6: VCI-PSI | B6: 12.1
A7: POI-WMI | B7: 15.2
A8: WMI-PSI | B8: 12.97
A10: VIQ-PIQ | B10: 9.98
A11: VCI-POI | B11: 11.45
A12: VCI-WMI | B12: 10.65
A13: POI-PSI | B13: 11.9
A14: VCI-PSI | B14: 10.78
... A88: WMI-PSI | B88: 13.14

Sheet b2
B1: VIQ-PIQ | C1: VCI-POI | D1: VCI-WMI | E1: POI-PSI | F1: VCI-PSI | G1: POI-WMI | H1: WMI-PSI
A2: 40 | B2: 0.1 | C2: 0.1 | D2: 0.4 | E2: 0.8 | F2: 1.4 | G2: 0.3 | H2: 0.8
A3: 39 | B3: 0.2 | C3: 0.1 | D3: 0.8 | E3: 0.8 | F3: 1.6 | G3: 0.3 | H3: 0.9
A4: 38 | B4: 0.2 | C4: 0.1 | D4: 0.9 | E4: 0.9 | F4: 1.7 | G4: 0.4 | H4: 1.2
A5: 37 | B5: 0.3 | C5: 0.7 | D5: 1 | E5: 1.4 | F5: 1.8 | G5: 0.8 | H5: 1.3
A6: 36 | B6: 0.4 | C6: 0.9 | D6: 1.2 | E6: 1.8 | F6: 2 | G6: 1 | H6: 1.4
A7: 35 | B7: 0.5 | C7: 1.3 | D7: 1.4 | E7: 2.1 | F7: 2.2 | G7: 1.6 | H7: 2
A8: 34 | B8: 0.8 | C8: 1.6 | D8: 1.5 | E8: 2.5 | F8: 2.6 | G8: 1.6 | H8: 2.2
A9: 33 | B9: 1.4 | C9: 2 | D9: 1.6 | E9: 2.9 | F9: 3.4 | G9: 1.7 | H9: 2.6
A10: 32 | B10: 1.6 | C10: 2.2 | D10: 2 | E10: 3.5 | F10: 4.3 | G10: 2.3 | H10: 3.1
A11: 31 | B11: 1.7 | C11: 3.1 | D11: 2.2 | E11: 3.8 | F11: 4.6 | G11: 3.3 | H11: 3.7
A12: 30 | B12: 1.8 | C12: 3.5 | D12: 2.6 | E12: 4.2 | F12: 5.1 | G12: 3.6 | H12: 4.7
A13: 29 | B13: 2.3 | C13: 4.9 | D13: 3.7 | E13: 5.5 | F13: 7.4 | G13: 4.3 | H13: 5.4
... A42: 0 | B42: 100 | C42: 100 | D42: 100 | E42: 100 | F42: 100 | G42: 100 | H42: 100

Sheet b3
B1: 7+7 | C1: 14
A2: sõnavara | B2: 3.63 | C2: 4.09
A3: sarnasused | B3: 3.87 | C3: 4.35
A4: aritmeetika | B4: 3.84 | C4: 4.32
A5: arvumälu | B5: 3.87 | C5: 4.35
A6: informeeritus | B6: 3.63 | C6: 4.09
A7: taibukus | B7: 3.83 | C7: 4.3
A8: täht-number j | B8: 4 | C8: 4.49
A9: piltide täiend | B9: 4.76 | C9: 4.56
A10: šifreering | B10: 4.36 | C10: 4.05
A11: kuubikud | B11: 4.65 | C11: 4.42
A12: maatriksid | B12: 4.42 | C12: 4.12
A13: pildiseeriad | B13: 5.07 | C13: 4.94
... A15: kujundite mood | B15: 4.89 | C15: 4.72

Sheet b6
B1: edaspidi | C1: tagurpidi
A2: 9 | B2: 3.7 | C2: 0
A3: 8 | B3: 14 | C3: 8.4
A4: 7 | B4: 39.3 | C4: 20.6
A5: 6 | B5: 77.6 | C5: 38.3
A6: 5 | B6: 96.3 | C6: 76.6
A7: 4 | B7: 99.1 | C7: 93.5
A8: 3 | B8: 100 | C8: 99.1
A9: 2 | B9: 100 | C9: 100
A10: 0 | B10: 100 | C10: 100
A12: 9 | B12: 3.7 | C12: 0
A13: 8 | B13: 18.5 | C13: 4.4
A14: 7 | B14: 46.7 | C14: 17
... A50: 0 | B50: 100 | C50: 100

Sheet b7
A1: 7 | B1: 0
A2: 6 | B2: 0
A3: 5 | B3: 0.9
A4: 4 | B4: 1.9
A5: 3 | B5: 7.5
A6: 2 | B6: 29.9
A7: 1 | B7: 66.4
A8: 0 | B8: 86.9
A9: -1 | B9: 100
A10: -2 | B10: 100
A11: -3 | B11: 100
A12: -4 | B12: 100
... A64: -4 | B64: 100

Sheet vanusegrupp
A1: 16 | B1: 1 | C1: 1
A2: 17 | B2: 1 | C2: 1
A3: 18 | B3: 2 | C3: 1
A4: 19 | B4: 2 | C4: 1
A5: 20 | B5: 3 | C5: 2
A6: 21 | B6: 3 | C6: 2
A7: 22 | B7: 3 | C7: 2
A8: 23 | B8: 3 | C8: 2
A9: 24 | B9: 3 | C9: 2
A10: 25 | B10: 4 | C10: 2
A11: 26 | B11: 4 | C11: 2
A12: 27 | B12: 4 | C12: 2
... A74: 89 | B74: 11 | C74: 5
